Workbook

Sheet Crias
C1: FAZENDAS TANGARÁ / ALMAS -SÃO FCO. DO CONDE -BA
C2: CONTROLE DE PRODUÇÃO E COMERCIALIZAÇÃO DE GADO DE CORTE - Periodo de agosto de 2013 á 2025
B4: Matriz | C4: N. de Ordem | D4: Reg.Nasc. | E4: Raça Pelagem | F4: Sexo | G4: Data Parto | H4: Pai | I4: Matriz | J4: Origem | K4: Vendido para | L4: Observação | M4: Data da venda | N4: Peso (@) | O4: Preço Real | P4: Sócios | Q4: Peso | R4: Indice de Ganho
A5: =IF(COUNTIF(B5:$B$5014,B5)>1,IF(COUNTIF($B$5:B5,B5)>1,"",B5&"-I"),B5) -> 871-I | B5: =+I5 -> 871 | C5: 1 | D5: 3 | F5: F | G5: 39625 | I5: 871 | J5: Cria da Fazenda | K5: não registrado
A6: =IF(COUNTIF(B6:$B$5014,B6)>1,IF(COUNTIF($B$5:B6,B6)>1,"",B6&"-I"),B6) -> 870-I | B6: =+I6 -> 870 | C6: 2 | D6: 4 | F6: F | G6: 39669 | I6: 870 | J6: Cria da Fazenda | K6: não registrado
A7: =IF(COUNTIF(B7:$B$5014,B7)>1,IF(COUNTIF($B$5:B7,B7)>1,"",B7&"-I"),B7) -> 872-I | B7: =+I7 -> 872 | C7: 3 | D7: 5 | F7: F | G7: 39670 | I7: 872 | J7: Cria da Fazenda | K7: não registrado
A8: =IF(COUNTIF(B8:$B$5014,B8)>1,IF(COUNTIF($B$5:B8,B8)>1,"",B8&"-I"),B8) -> 863-I | B8: =+I8 -> 863 | C8: 4 | D8: 8 | F8: M | G8: 39647 | I8: 863 | J8: Cria da Fazenda | K8: não registrado
A9: =IF(COUNTIF(B9:$B$5014,B9)>1,IF(COUNTIF($B$5:B9,B9)>1,"",B9&"-I"),B9) -> 859-I | B9: =+I9 -> 859 | C9: 5 | D9: 9 | F9: M | G9: 39676 | I9: 859 | J9: Cria da Fazenda | K9: não registrado
A10: =IF(COUNTIF(B10:$B$5014,B10)>1,IF(COUNTIF($B$5:B10,B10)>1,"",B10&"-I"),B10) -> 889-I | B10: =+I10 -> 889 | C10: 6 | D10: 11 | F10: M | G10: 39676 | I10: 889 | J10: Cria da Fazenda | K10: não registrado
A11: =IF(COUNTIF(B11:$B$5014,B11)>1,IF(COUNTIF($B$5:B11,B11)>1,"",B11&"-I"),B11) -> 882-I | B11: =+I11 -> 882 | C11: 7 | D11: 14 | F11: M | G11: 39631 | I11: 882 | J11: Cria da Fazenda | K11: não registrado
A12: =IF(COUNTIF(B12:$B$5014,B12)>1,IF(COUNTIF($B$5:B12,B12)>1,"",B12&"-I"),B12) -> 854-I | B12: =+I12 -> 854 | C12: 8 | D12: 15 | F12: M | G12: 39633 | I12: 854 | J12: Cria da Fazenda | K12: não registrado
A13: =IF(COUNTIF(B13:$B$5014,B13)>1,IF(COUNTIF($B$5:B13,B13)>1,"",B13&"-I"),B13) -> 873-I | B13: =+I13 -> 873 | C13: 9 | D13: 16 | F13: F | G13: 39715 | I13: 873 | J13: Cria da Fazenda | K13: não registrado
A14: =IF(COUNTIF(B14:$B$5014,B14)>1,IF(COUNTIF($B$5:B14,B14)>1,"",B14&"-I"),B14) -> 880-I | B14: =+I14 -> 880 | C14: 10 | D14: 19 | F14: F | G14: 39752 | I14: 880 | J14: Cria da Fazenda | K14: não registrado
A15: =IF(COUNTIF(B15:$B$5014,B15)>1,IF(COUNTIF($B$5:B15,B15)>1,"",B15&"-I"),B15) -> 881-I | B15: =+I15 -> 881 | C15: 11 | D15: 23 | F15: F | G15: 39754 | I15: 881 | J15: Cria da Fazenda | K15: não registrado
A16: =IF(COUNTIF(B16:$B$5014,B16)>1,IF(COUNTIF($B$5:B16,B16)>1,"",B16&"-I"),B16) -> 886-I | B16: =+I16 -> 886 | C16: 12 | D16: 24 | F16: F | G16: 39755 | I16: 886 | J16: Cria da Fazenda | K16: não registrado
A17: =IF(COUNTIF(B17:$B$5014,B17)>1,IF(COUNTIF($B$5:B17,B17)>1,"",B17&"-I"),B17) -> 897-I | B17: =+I17 -> 897 | C17: 013 | D17: 25 | F17: M | G17: 39755 | I17: 897 | J17: Cria da Fazenda | K17: não registrado
A18: =IF(COUNTIF(B18:$B$5014,B18)>1,IF(COUNTIF($B$5:B18,B18)>1,"",B18&"-I"),B18) -> 898-I | B18: =+I18 -> 898 | C18: 014 | D18: 26 | F18: F | G18: 39790 | I18: 898 | J18: Cria da Fazenda | K18: não registrado
A19: =IF(COUNTIF(B19:$B$5014,B19)>1,IF(COUNTIF($B$5:B19,B19)>1,"",B19&"-I"),B19) -> 890-I | B19: =+I19 -> 890 | C19: 015 | D19: 27 | F19: F | G19: 39788 | I19: 890 | J19: Cria da Fazenda | K19: não registrado
A20: =IF(COUNTIF(B20:$B$5014,B20)>1,IF(COUNTIF($B$5:B20,B20)>1,"",B20&"-I"),B20) -> 885-I | B20: =+I20 -> 885 | C20: 016 | D20: 31 | F20: F | G20: 39834 | I20: 885 | J20: Cria da Fazenda | K20: não registrado
A21: =IF(COUNTIF(B21:$B$5014,B21)>1,IF(COUNTIF($B$5:B21,B21)>1,"",B21&"-I"),B21) -> 877-I | B21: =+I21 -> 877 | C21: 017 | D21: 32 | F21: M | G21: 39835 | I21: 877 | J21: Cria da Fazenda | K21: não registrado
A22: =IF(COUNTIF(B22:$B$5014,B22)>1,IF(COUNTIF($B$5:B22,B22)>1,"",B22&"-I"),B22) -> 869-I | B22: =+I22 -> 869 | C22: 018 | D22: 33 | F22: F | G22: 39842 | I22: 869 | J22: Cria da Fazenda | K22: não registrado
A23: =IF(COUNTIF(B23:$B$5014,B23)>1,IF(COUNTIF($B$5:B23,B23)>1,"",B23&"-I"),B23) -> 926-I | B23: =+I23 -> 926 | C23: 019 | D23: 35 | F23: F | G23: 39838 | I23: 926 | J23: Cria da Fazenda | K23: não registrado
A24: =IF(COUNTIF(B24:$B$5014,B24)>1,IF(COUNTIF($B$5:B24,B24)>1,"",B24&"-I"),B24) -> 858-I | B24: =+I24 -> 858 | C24: 020 | D24: 36 | F24: F | G24: 39840 | I24: 858 | J24: Cria da Fazenda | K24: não registrado
A25: =IF(COUNTIF(B25:$B$5014,B25)>1,IF(COUNTIF($B$5:B25,B25)>1,"",B25&"-I"),B25) -> 862-I | B25: =+I25 -> 862 | C25: 021 | D25: 37 | F25: F | G25: 39842 | I25: 862 | J25: Cria da Fazenda | K25: não registrado
A26: =IF(COUNTIF(B26:$B$5014,B26)>1,IF(COUNTIF($B$5:B26,B26)>1,"",B26&"-I"),B26) -> 900-I | B26: =+I26 -> 900 | C26: 022 | D26: 40 | F26: M | G26: 39846 | I26: 900 | J26: Cria da Fazenda | K26: não registrado
A27: =IF(COUNTIF(B27:$B$5014,B27)>1,IF(COUNTIF($B$5:B27,B27)>1,"",B27&"-I"),B27) -> 874-I | B27: =+I27 -> 874 | C27: 023 | D27: 42 | F27: F | G27: 39846 | I27: 874 | J27: Cria da Fazenda | K27: não registrado
A28: =IF(COUNTIF(B28:$B$5014,B28)>1,IF(COUNTIF($B$5:B28,B28)>1,"",B28&"-I"),B28) -> 894-I | B28: =+I28 -> 894 | C28: 024 | D28: 43 | F28: F | G28: 39846 | I28: 894 | J28: Cria da Fazenda | K28: não registrado
... A63: =IF(COUNTIF(B63:$B$5014,B63)>1,IF(COUNTIF($B$5:B63,B63)>1,"",B63&"-I"),B63) | B63: =+I63 -> 859 | C63: 059 | D63: 108 | F63: M | G63: 40177 | I63: 859 | J63: Cria da Fazenda | K63: não registrado
A64: =IF(COUNTIF(B64:$B$5014,B64)>1,IF(COUNTIF($B$5:B64,B64)>1,"",B64&"-I"),B64) -> 936-I | B64: =+I64 -> 936 | C64: 060 | D64: S/R | F64: F | G64: 40056 | I64: 936 | J64: Cria da Fazenda | K64: Morto | L64: Morreu nasc. Prematuro | M64: xxxxx | N64: xxxxx | O64: xxxxx
A65: =IF(COUNTIF(B65:$B$5014,B65)>1,IF(COUNTIF($B$5:B65,B65)>1,"",B65&"-I"),B65) | B65: =+I65 -> 926 | C65: 061 | D65: S/R | F65: F | G65: 40289 | I65: 926 | J65: Cria da Fazenda | K65: não registrado
A66: =IF(COUNTIF(B66:$B$5014,B66)>1,IF(COUNTIF($B$5:B66,B66)>1,"",B66&"-I"),B66) | B66: =+I66 -> 870 | C66: 062 | D66: 75 | F66: F | G66: 40315 | I66: 870 | J66: Cria da Fazenda | K66: não registrado
A67: =IF(COUNTIF(B67:$B$5014,B67)>1,IF(COUNTIF($B$5:B67,B67)>1,"",B67&"-I"),B67) | B67: =+I67 -> 862 | C67: 063 | D67: 75 | F67: M | G67: 40330 | I67: 862 | J67: Cria da Fazenda | K67: não registrado
A68: =IF(COUNTIF(B68:$B$5014,B68)>1,IF(COUNTIF($B$5:B68,B68)>1,"",B68&"-I"),B68) | B68: =+I68 -> 882 | C68: 064 | D68: 82 | F68: M | G68: 40368 | I68: 882 | J68: Cria da Fazenda | K68: não registrado
A69: =IF(COUNTIF(B69:$B$5014,B69)>1,IF(COUNTIF($B$5:B69,B69)>1,"",B69&"-I"),B69) | B69: =+I69 -> 936 | C69: 065 | D69: 85 | F69: M | G69: 40383 | I69: 936 | J69: Cria da Fazenda | K69: não registrado
A70: =IF(COUNTIF(B70:$B$5014,B70)>1,IF(COUNTIF($B$5:B70,B70)>1,"",B70&"-I"),B70) | B70: =+I70 -> 896 | C70: 066 | D70: 86 | F70: M | G70: 40394 | I70: 896 | J70: Cria da Fazenda | K70: não registrado
A71: =IF(COUNTIF(B71:$B$5014,B71)>1,IF(COUNTIF($B$5:B71,B71)>1,"",B71&"-I"),B71) | B71: =+I71 -> 876 | C71: 067 | D71: 89 | F71: M | G71: 40343 | I71: 876 | J71: Cria da Fazenda | K71: não registrado
A72: =IF(COUNTIF(B72:$B$5014,B72)>1,IF(COUNTIF($B$5:B72,B72)>1,"",B72&"-I"),B72) | B72: =+I72 -> 867 | C72: 068 | D72: 91 | F72: M | G72: 40338 | I72: 867 | J72: Cria da Fazenda | K72: não registrado
A73: =IF(COUNTIF(B73:$B$5014,B73)>1,IF(COUNTIF($B$5:B73,B73)>1,"",B73&"-I"),B73) | B73: =+I73 -> 874 | C73: 069 | D73: 97 | F73: M | G73: 40400 | I73: 874 | J73: Cria da Fazenda | K73: não registrado
A74: =IF(COUNTIF(B74:$B$5014,B74)>1,IF(COUNTIF($B$5:B74,B74)>1,"",B74&"-I"),B74) | B74: =+I74 -> 871 | C74: 070 | D74: 99 | F74: M | G74: 40345 | I74: 871 | J74: Cria da Fazenda | K74: não registrado
A75: =IF(COUNTIF(B75:$B$5014,B75)>1,IF(COUNTIF($B$5:B75,B75)>1,"",B75&"-I"),B75) | B75: =+I75 -> 900 | C75: 071 | D75: 100 | F75: M | G75: 40426 | I75: 900 | J75: Cria da Fazenda | K75: não registrado
...

Sheet Matrizes
H1: =+I3-15*30 -> -450 | I1: =+I3-12*30 -> -360
B2: FAZENDAS TANGARÁ / ALMAS - MUNICIPIO SÃO FRANCISCO DO CONDE - BA
B3: INICIO: | C3: 2008 | D3: 44866 | H3: POSIÇÃO EM:
A4: Ant | B4: Nº Ord. | C4: Nº Reg. | D4: 1ª Cria | E4: ULT. Cria | F4: Meses + 9,5 Meses | G4: Nº Crias | H4: Meses/Cria | I4: OBS
C5: 854 | D5: =IFERROR(VLOOKUP(C5&"-I",Crias!$A$5:$G$6221,7,FALSE),E5) -> 39633 | E5: =IFERROR(IF(C5="","",VLOOKUP(C5,Crias!$A$5:$G$6221,7,FALSE)),"Novilha") -> 44569 | F5: =IFERROR(IF(D5="","",((E5-D5+1)/30)+9.5),"S/R") -> 174.06667 | G5: =IF(F5="","",COUNTIF(Crias!$B$5:$B$6221,Matrizes!C5)+A5) -> 13 | H5: =IFERROR(F5/G5,"") -> 13.389744 | I5: mor.17/10/23, debili.apos passar uma noite atolada no mangue.-pasto 5/A.
C6: 858 | D6: =IFERROR(VLOOKUP(C6&"-I",Crias!$A$5:$G$6221,7,FALSE),E6) -> 39840 | E6: =IFERROR(IF(C6="","",VLOOKUP(C6,Crias!$A$5:$G$6221,7,FALSE)),"Novilha") -> 45548 | F6: =IFERROR(IF(D6="","",((E6-D6+1)/30)+9.5),"S/R") -> 199.8 | G6: =IF(F6="","",COUNTIF(Crias!$B$5:$B$6221,Matrizes!C6)+A6) -> 13 | H6: =IFERROR(F6/G6,"") -> 15.369231 | I6: Descartada c/11@ p/ Luciano Moraes.em 02/26.
C7: 859 | D7: =IFERROR(VLOOKUP(C7&"-I",Crias!$A$5:$G$6221,7,FALSE),E7) -> 39676 | E7: =IFERROR(IF(C7="","",VLOOKUP(C7,Crias!$A$5:$G$6221,7,FALSE)),"Novilha") -> 45335 | F7: =IFERROR(IF(D7="","",((E7-D7+1)/30)+9.5),"S/R") -> 198.16667 | G7: =IF(F7="","",COUNTIF(Crias!$B$5:$B$6221,Matrizes!C7)+A7) -> 13 | H7: =IFERROR(F7/G7,"") -> 15.24359 | I7: Descartada c/11@ p/ Luciano Moraes.em 02/26.
B8: 1 | C8: 860 | D8: =IFERROR(VLOOKUP(C8&"-I",Crias!$A$5:$G$6221,7,FALSE),E8) -> 40099 | E8: =IFERROR(IF(C8="","",VLOOKUP(C8,Crias!$A$5:$G$6221,7,FALSE)),"Novilha") -> 46045 | F8: =IFERROR(IF(D8="","",((E8-D8+1)/30)+9.5),"S/R") -> 207.73333 | G8: =IF(F8="","",COUNTIF(Crias!$B$5:$B$6221,Matrizes!C8)+A8) -> 12 | H8: =IFERROR(F8/G8,"") -> 17.311111
C9: 862 | D9: =IFERROR(VLOOKUP(C9&"-I",Crias!$A$5:$G$6221,7,FALSE),E9) -> 39842 | E9: =IFERROR(IF(C9="","",VLOOKUP(C9,Crias!$A$5:$G$6221,7,FALSE)),"Novilha") -> 44893 | F9: =IFERROR(IF(D9="","",((E9-D9+1)/30)+9.5),"S/R") -> 177.9 | G9: =IF(F9="","",COUNTIF(Crias!$B$5:$B$6221,Matrizes!C9)+A9) -> 12 | H9: =IFERROR(F9/G9,"") -> 14.825 | I9: Perdida no Bambuzal
B10: =IF(C10="","",+LARGE($B$5:B9,1)+1) -> 2 | C10: 863 | D10: =IFERROR(VLOOKUP(C10&"-I",Crias!$A$5:$G$6221,7,FALSE),E10) -> 39647 | E10: =IFERROR(IF(C10="","",VLOOKUP(C10,Crias!$A$5:$G$6221,7,FALSE)),"Novilha") -> 45486 | F10: =IFERROR(IF(D10="","",((E10-D10+1)/30)+9.5),"S/R") -> 204.16667 | G10: =IF(F10="","",COUNTIF(Crias!$B$5:$B$6221,Matrizes!C10)+A10) -> 13 | H10: =IFERROR(F10/G10,"") -> 15.705128
C11: 865 | D11: =IFERROR(VLOOKUP(C11&"-I",Crias!$A$5:$G$6221,7,FALSE),E11) -> 40031 | E11: =IFERROR(IF(C11="","",VLOOKUP(C11,Crias!$A$5:$G$6221,7,FALSE)),"Novilha") -> 45196 | F11: =IFERROR(IF(D11="","",((E11-D11+1)/30)+9.5),"S/R") -> 181.7 | G11: =IF(F11="","",COUNTIF(Crias!$B$5:$B$6221,Matrizes!C11)+A11) -> 12 | H11: =IFERROR(F11/G11,"") -> 15.141667 | I11: mor.09/10/23.debili.apos uma noite presa a pata traz.na cerca.Deixou BEZ..
B12: =IF(C12="","",+LARGE($B$5:B11,1)+1) -> 3 | C12: 867 | D12: =IFERROR(VLOOKUP(C12&"-I",Crias!$A$5:$G$6221,7,FALSE),E12) -> 40047 | E12: =IFERROR(IF(C12="","",VLOOKUP(C12,Crias!$A$5:$G$6221,7,FALSE)),"Novilha") -> 45944 | F12: =IFERROR(IF(D12="","",((E12-D12+1)/30)+9.5),"S/R") -> 206.1 | G12: =IF(F12="","",COUNTIF(Crias!$B$5:$B$6221,Matrizes!C12)+A12) -> 15 | H12: =IFERROR(F12/G12,"") -> 13.74
C13: 869 | D13: =IFERROR(VLOOKUP(C13&"-I",Crias!$A$5:$G$6221,7,FALSE),E13) -> 39842 | E13: =IFERROR(IF(C13="","",VLOOKUP(C13,Crias!$A$5:$G$6221,7,FALSE)),"Novilha") -> 44646 | F13: =IFERROR(IF(D13="","",((E13-D13+1)/30)+9.5),"S/R") -> 169.66667 | G13: =IF(F13="","",COUNTIF(Crias!$B$5:$B$6221,Matrizes!C13)+A13) -> 10 | H13: =IFERROR(F13/G13,"") -> 16.966667 | I13: Descartada em 10/23 c/11,7@
C14: 870 | D14: =IFERROR(VLOOKUP(C14&"-I",Crias!$A$5:$G$6221,7,FALSE),E14) -> 39669 | E14: =IFERROR(IF(C14="","",VLOOKUP(C14,Crias!$A$5:$G$6221,7,FALSE)),"Novilha") -> 44605 | F14: =IFERROR(IF(D14="","",((E14-D14+1)/30)+9.5),"S/R") -> 174.06667 | G14: =IF(F14="","",COUNTIF(Crias!$B$5:$B$6221,Matrizes!C14)+A14) -> 13 | H14: =IFERROR(F14/G14,"") -> 13.389744 | I14: morreu em 18/08/23 mordida por cobra.
C15: 871 | D15: =IFERROR(VLOOKUP(C15&"-I",Crias!$A$5:$G$6221,7,FALSE),E15) -> 39625 | E15: =IFERROR(IF(C15="","",VLOOKUP(C15,Crias!$A$5:$G$6221,7,FALSE)),"Novilha") -> 43423 | F15: =IFERROR(IF(D15="","",((E15-D15+1)/30)+9.5),"S/R") -> 136.13333 | G15: =IF(F15="","",COUNTIF(Crias!$B$5:$B$6221,Matrizes!C15)+A15) -> 10 | H15: =IFERROR(F15/G15,"") -> 13.613333 | I15: descartada em 06/21 - c/10,5@ - prob. Bez. Mumificado
C16: 872 | D16: =IFERROR(VLOOKUP(C16&"-I",Crias!$A$5:$G$6221,7,FALSE),E16) -> 39670 | E16: =IFERROR(IF(C16="","",VLOOKUP(C16,Crias!$A$5:$G$6221,7,FALSE)),"Novilha") -> 43834 | F16: =IFERROR(IF(D16="","",((E16-D16+1)/30)+9.5),"S/R") -> 148.33333 | G16: =IF(F16="","",COUNTIF(Crias!$B$5:$B$6221,Matrizes!C16)+A16) -> 11 | H16: =IFERROR(F16/G16,"") -> 13.484848
C17: 873 | D17: =IFERROR(VLOOKUP(C17&"-I",Crias!$A$5:$G$6221,7,FALSE),E17) -> 39715 | E17: =IFERROR(IF(C17="","",VLOOKUP(C17,Crias!$A$5:$G$6221,7,FALSE)),"Novilha") -> 45369 | F17: =IFERROR(IF(D17="","",((E17-D17+1)/30)+9.5),"S/R") -> 198 | G17: =IF(F17="","",COUNTIF(Crias!$B$5:$B$6221,Matrizes!C17)+A17) -> 15 | H17: =IFERROR(F17/G17,"") -> 13.2 | I17: Descartada c/12@ p/Arlindo em 12/25.
B18: =IF(C18="","",+LARGE($B$5:B17,1)+1) -> 4 | C18: 874 | D18: =IFERROR(VLOOKUP(C18&"-I",Crias!$A$5:$G$6221,7,FALSE),E18) -> 39846 | E18: =IFERROR(IF(C18="","",VLOOKUP(C18,Crias!$A$5:$G$6221,7,FALSE)),"Novilha") -> 46105 | F18: =IFERROR(IF(D18="","",((E18-D18+1)/30)+9.5),"S/R") -> 218.16667 | G18: =IF(F18="","",COUNTIF(Crias!$B$5:$B$6221,Matrizes!C18)+A18) -> 12 | H18: =IFERROR(F18/G18,"") -> 18.180556
C19: 875 | D19: =IFERROR(VLOOKUP(C19&"-I",Crias!$A$5:$G$6221,7,FALSE),E19) -> 39853 | E19: =IFERROR(IF(C19="","",VLOOKUP(C19,Crias!$A$5:$G$6221,7,FALSE)),"Novilha") -> 44197 | F19: =IFERROR(IF(D19="","",((E19-D19+1)/30)+9.5),"S/R") -> 154.33333 | G19: =IF(F19="","",COUNTIF(Crias!$B$5:$B$6221,Matrizes!C19)+A19) -> 10 | H19: =IFERROR(F19/G19,"") -> 15.433333 | I19: Descartada em 02/02.
C20: 876 | D20: =IFERROR(VLOOKUP(C20&"-I",Crias!$A$5:$G$6221,7,FALSE),E20) -> 39851 | E20: =IFERROR(IF(C20="","",VLOOKUP(C20,Crias!$A$5:$G$6221,7,FALSE)),"Novilha") -> 45673 | F20: =IFERROR(IF(D20="","",((E20-D20+1)/30)+9.5),"S/R") -> 203.6 | G20: =IF(F20="","",COUNTIF(Crias!$B$5:$B$6221,Matrizes!C20)+A20) -> 14 | H20: =IFERROR(F20/G20,"") -> 14.542857 | I20: Descartada c/11@ p/ Luciano Moraes.em 02/26.
C21: 877 | D21: =IFERROR(VLOOKUP(C21&"-I",Crias!$A$5:$G$6221,7,FALSE),E21) -> 39835 | E21: =IFERROR(IF(C21="","",VLOOKUP(C21,Crias!$A$5:$G$6221,7,FALSE)),"Novilha") -> 44510 | F21: =IFERROR(IF(D21="","",((E21-D21+1)/30)+9.5),"S/R") -> 165.36667 | G21: 12 | H21: =IFERROR(F21/G21,"") -> 13.780556 | I21: Descartada em 10/23 c/11,7@
C22: 880 | D22: =IFERROR(VLOOKUP(C22&"-I",Crias!$A$5:$G$6221,7,FALSE),E22) -> 39752 | E22: =IFERROR(IF(C22="","",VLOOKUP(C22,Crias!$A$5:$G$6221,7,FALSE)),"Novilha") -> 44821 | F22: =IFERROR(IF(D22="","",((E22-D22+1)/30)+9.5),"S/R") -> 178.5 | G22: =IF(F22="","",COUNTIF(Crias!$B$5:$B$6221,Matrizes!C22)+A22) -> 12 | H22: =IFERROR(F22/G22,"") -> 14.875 | I22: Descartada em 10/23 c/11,7@
C23: 881 | D23: =IFERROR(VLOOKUP(C23&"-I",Crias!$A$5:$G$6221,7,FALSE),E23) -> 39754 | E23: =IFERROR(IF(C23="","",VLOOKUP(C23,Crias!$A$5:$G$6221,7,FALSE)),"Novilha") -> 45684 | F23: =IFERROR(IF(D23="","",((E23-D23+1)/30)+9.5),"S/R") -> 207.2 | G23: =IF(F23="","",COUNTIF(Crias!$B$5:$B$6221,Matrizes!C23)+A23) -> 15 | H23: =IFERROR(F23/G23,"") -> 13.813333 | I23: descartada em 12/25 Arlindo 12,0@
C24: 882 | D24: =IFERROR(VLOOKUP(C24&"-I",Crias!$A$5:$G$6221,7,FALSE),E24) -> 39631 | E24: =IFERROR(IF(C24="","",VLOOKUP(C24,Crias!$A$5:$G$6221,7,FALSE)),"Novilha") -> 44287 | F24: =IFERROR(IF(D24="","",((E24-D24+1)/30)+9.5),"S/R") -> 164.73333 | G24: =IF(F24="","",COUNTIF(Crias!$B$5:$B$6221,Matrizes!C24)+A24) -> 11 | H24: =IFERROR(F24/G24,"") -> 14.975758 | I24: Descartada em 10/23 c/11,7@
C25: 884 | D25: =IFERROR(VLOOKUP(C25&"-I",Crias!$A$5:$G$6221,7,FALSE),E25) -> 39854 | E25: =IFERROR(IF(C25="","",VLOOKUP(C25,Crias!$A$5:$G$6221,7,FALSE)),"Novilha") -> 44939 | F25: =IFERROR(IF(D25="","",((E25-D25+1)/30)+9.5),"S/R") -> 179.03333 | G25: =IF(F25="","",COUNTIF(Crias!$B$5:$B$6221,Matrizes!C25)+A25) -> 12 | H25: =IFERROR(F25/G25,"") -> 14.919444 | I25: Descartada em 10/23 c/11,7@
C26: 885 | D26: =IFERROR(VLOOKUP(C26&"-I",Crias!$A$5:$G$6221,7,FALSE),E26) -> 39834 | E26: =IFERROR(IF(C26="","",VLOOKUP(C26,Crias!$A$5:$G$6221,7,FALSE)),"Novilha") -> 44894 | F26: =IFERROR(IF(D26="","",((E26-D26+1)/30)+9.5),"S/R") -> 178.2 | G26: =IF(F26="","",COUNTIF(Crias!$B$5:$B$6221,Matrizes!C26)+A26) -> 12 | H26: =IFERROR(F26/G26,"") -> 14.85 | I26: Descartada em 10/23 c/11,7@
C27: 886 | D27: =IFERROR(VLOOKUP(C27&"-I",Crias!$A$5:$G$6221,7,FALSE),E27) -> 39755 | E27: =IFERROR(IF(C27="","",VLOOKUP(C27,Crias!$A$5:$G$6221,7,FALSE)),"Novilha") -> 45404 | F27: =IFERROR(IF(D27="","",((E27-D27+1)/30)+9.5),"S/R") -> 197.83333 | G27: =IF(F27="","",COUNTIF(Crias!$B$5:$B$6221,Matrizes!C27)+A27) -> 14 | H27: =IFERROR(F27/G27,"") -> 14.130952 | I27: descartada p/abate em 20/07/25 p/Arlindo com 13,5 @
C28: 889 | D28: =IFERROR(VLOOKUP(C28&"-I",Crias!$A$5:$G$6221,7,FALSE),E28) -> 39676 | E28: =IFERROR(IF(C28="","",VLOOKUP(C28,Crias!$A$5:$G$6221,7,FALSE)),"Novilha") -> 44860 | F28: =IFERROR(IF(D28="","",((E28-D28+1)/30)+9.5),"S/R") -> 182.33333 | G28: =IF(F28="","",COUNTIF(Crias!$B$5:$B$6221,Matrizes!C28)+A28) -> 12 | H28: =IFERROR(F28/G28,"") -> 15.194444 | I28: morreu em 10/04//23, envenenada por ervas daninha.
B29: =IF(C29="","",+LARGE($B$5:B28,1)+1) -> 5 | C29: 893 | D29: =IFERROR(VLOOKUP(C29&"-I",Crias!$A$5:$G$6221,7,FALSE),E29) -> 39951 | E29: =IFERROR(IF(C29="","",VLOOKUP(C29,Crias!$A$5:$G$6221,7,FALSE)),"Novilha") -> 45835 | F29: =IFERROR(IF(D29="","",((E29-D29+1)/30)+9.5),"S/R") -> 205.66667 | G29: =IF(F29="","",COUNTIF(Crias!$B$5:$B$6221,Matrizes!C29)+A29) -> 12 | H29: =IFERROR(F29/G29,"") -> 17.138889
C30: 894 | D30: =IFERROR(VLOOKUP(C30&"-I",Crias!$A$5:$G$6221,7,FALSE),E30) -> 39846 | E30: =IFERROR(IF(C30="","",VLOOKUP(C30,Crias!$A$5:$G$6221,7,FALSE)),"Novilha") -> 45792 | F30: =IFERROR(IF(D30="","",((E30-D30+1)/30)+9.5),"S/R") -> 207.73333 | G30: =IF(F30="","",COUNTIF(Crias!$B$5:$B$6221,Matrizes!C30)+A30) -> 13 | H30: =IFERROR(F30/G30,"") -> 15.979487 | I30: morreu mordida p/cobra em 17/07/25 /beza.amamentada p/mat. 1020.
C31: 896 | D31: =IFERROR(VLOOKUP(C31&"-I",Crias!$A$5:$G$6221,7,FALSE),E31) -> 39878 | E31: =IFERROR(IF(C31="","",VLOOKUP(C31,Crias!$A$5:$G$6221,7,FALSE)),"Novilha") -> 43476 | F31: =IFERROR(IF(D31="","",((E31-D31+1)/30)+9.5),"S/R") -> 129.46667 | G31: =IF(F31="","",COUNTIF(Crias!$B$5:$B$6221,Matrizes!C31)+A31) -> 9 | H31: =IFERROR(F31/G31,"") -> 14.385185 | I31: descartada em 03/20 - c/12@ - devido prob. de ciclagem
C32: 897 | D32: =IFERROR(VLOOKUP(C32&"-I",Crias!$A$5:$G$6221,7,FALSE),E32) -> 39755 | E32: =IFERROR(IF(C32="","",VLOOKUP(C32,Crias!$A$5:$G$6221,7,FALSE)),"Novilha") -> 43692 | F32: =IFERROR(IF(D32="","",((E32-D32+1)/30)+9.5),"S/R") -> 140.76667 | G32: =IF(F32="","",COUNTIF(Crias!$B$5:$B$6221,Matrizes!C32)+A32) -> 10 | H32: =IFERROR(F32/G32,"") -> 14.076667 | I32: descartada em 11/20 - c/11,5 @, devido prob.de ciclagem.
C33: 898 | D33: =IFERROR(VLOOKUP(C33&"-I",Crias!$A$5:$G$6221,7,FALSE),E33) -> 39790 | E33: =IFERROR(IF(C33="","",VLOOKUP(C33,Crias!$A$5:$G$6221,7,FALSE)),"Novilha") -> 44431 | F33: =IFERROR(IF(D33="","",((E33-D33+1)/30)+9.5),"S/R") -> 164.23333 | G33: =IF(F33="","",COUNTIF(Crias!$B$5:$B$6221,Matrizes!C33)+A33) -> 12 | H33: =IFERROR(F33/G33,"") -> 13.686111 | I33: Descartada em 10/23 c/11,7@
C34: 899 | D34: =IFERROR(VLOOKUP(C34&"-I",Crias!$A$5:$G$6221,7,FALSE),E34) -> 39976 | E34: =IFERROR(IF(C34="","",VLOOKUP(C34,Crias!$A$5:$G$6221,7,FALSE)),"Novilha") -> 45881 | F34: =IFERROR(IF(D34="","",((E34-D34+1)/30)+9.5),"S/R") -> 206.36667 | G34: =IF(F34="","",COUNTIF(Crias!$B$5:$B$6221,Matrizes!C34)+A34) -> 14 | H34: =IFERROR(F34/G34,"") -> 14.740476 | I34: Descartada c/11@ p/ Luciano Moraes.em 02/26.
C35: 926 | D35: =IFERROR(VLOOKUP(C35&"-I",Crias!$A$5:$G$6221,7,FALSE),E35) -> 39838 | E35: =IFERROR(IF(C35="","",VLOOKUP(C35,Crias!$A$5:$G$6221,7,FALSE)),"Novilha") -> 45628 | F35: =IFERROR(IF(D35="","",((E35-D35+1)/30)+9.5),"S/R") -> 202.53333 | G35: =IF(F35="","",COUNTIF(Crias!$B$5:$B$6221,Matrizes!C35)+A35) -> 14 | H35: =IFERROR(F35/G35,"") -> 14.466667 | I35: Perdida no Bambuzal
C36: 930 | D36: =IFERROR(VLOOKUP(C36&"-I",Crias!$A$5:$G$6221,7,FALSE),E36) -> 40051 | E36: =IFERROR(IF(C36="","",VLOOKUP(C36,Crias!$A$5:$G$6221,7,FALSE)),"Novilha") -> 45991 | F36: =IFERROR(IF(D36="","",((E36-D36+1)/30)+9.5),"S/R") -> 207.53333 | G36: =IF(F36="","",COUNTIF(Crias!$B$5:$B$6221,Matrizes!C36)+A36) -> 13 | H36: =IFERROR(F36/G36,"") -> 15.964103 | I36: .morr. deb.apos atol. Em poço da PB/3R.em12/02/26.bez. Ama.p/outra matriz.
B37: =IF(C37="","",+LARGE($B$5:B36,1)+1) -> 6 | C37: 931 | D37: =IFERROR(VLOOKUP(C37&"-I",Crias!$A$5:$G$6221,7,FALSE),E37) -> 40072 | E37: =IFERROR(IF(C37="","",VLOOKUP(C37,Crias!$A$5:$G$6221,7,FALSE)),"Novilha") -> 45393 | F37: =IFERROR(IF(D37="","",((E37-D37+1)/30)+9.5),"S/R") -> 186.9 | G37: =IF(F37="","",COUNTIF(Crias!$B$5:$B$6221,Matrizes!C37)+A37) -> 12 | H37: =IFERROR(F37/G37,"") -> 15.575
C38: 933 | D38: =IFERROR(VLOOKUP(C38&"-I",Crias!$A$5:$G$6221,7,FALSE),E38) -> 40059 | E38: =IFERROR(IF(C38="","",VLOOKUP(C38,Crias!$A$5:$G$6221,7,FALSE)),"Novilha") -> 45174 | F38: =IFERROR(IF(D38="","",((E38-D38+1)/30)+9.5),"S/R") -> 180.03333 | G38: =IF(F38="","",COUNTIF(Crias!$B$5:$B$6221,Matrizes!C38)+A38) -> 14 | H38: =IFERROR(F38/G38,"") -> 12.859524 | I38: Morreu em 18/04/24, mordida por cobra.
C39: 934 | D39: =IFERROR(VLOOKUP(C39&"-I",Crias!$A$5:$G$6221,7,FALSE),E39) -> 40060 | E39: =IFERROR(IF(C39="","",VLOOKUP(C39,Crias!$A$5:$G$6221,7,FALSE)),"Novilha") -> 45953 | F39: =IFERROR(IF(D39="","",((E39-D39+1)/30)+9.5),"S/R") -> 205.96667 | G39: =IF(F39="","",COUNTIF(Crias!$B$5:$B$6221,Matrizes!C39)+A39) -> 13 | H39: =IFERROR(F39/G39,"") -> 15.84359 | I39: Descartada c/11@ p/ Luciano Moraes.em 02/26.
C40: 936 | D40: =IFERROR(VLOOKUP(C40&"-I",Crias!$A$5:$G$6221,7,FALSE),E40) -> 40056 | E40: =IFERROR(IF(C40="","",VLOOKUP(C40,Crias!$A$5:$G$6221,7,FALSE)),"Novilha") -> 44993 | F40: =IFERROR(IF(D40="","",((E40-D40+1)/30)+9.5),"S/R") -> 174.1 | G40: =IF(F40="","",COUNTIF(Crias!$B$5:$B$6221,Matrizes!C40)+A40) -> 12 | H40: =IFERROR(F40/G40,"") -> 14.508333 | I40: debilitada morreu afogada na represa em15/02/25
...

Sheet Desempenho
B1: DESEMPENHO REPRODUTIVO DE MATRIZES
B2: DATA DO TOQUE: | D2: 45974 | E2: FAZENDAS ALMAS E TANGARA / SÃO FRANCISCO DO CONDE / BA. | M2: PERIODO | N2: 30/04/25 à 13/11/2025
B3: Nº ORD | C3: Nº DE REG. | D3: SITUAÇÃO ATUAL | E3: Nº DE CRIAS | F3: INT/CRIA MESES | G3: RESULT TOQUE | H3: PREV. PARTO | J3: CRUZ. | K3: DATA DO PARTO | L3: M/F-sex0 | M3: REG | N3: OBSESRVAÇÕES
A4: =IF(G4="VZ","",I4&1)&IF(K4>0,"-N","") -> 1 | B4: =+Matrizes!B5 -> 0 | C4: =+Matrizes!C5 -> 854 | D4: =+Matrizes!E5 -> 44569 | E4: =+Matrizes!G5 -> 13 | F4: =IFERROR(+Matrizes!H5,"") -> 13.389744 | H4: =IFERROR(IF(G4>0,+$D$2-G4+285,""),"xxxxx") | I4: =IFERROR(IF(G4>0,IF(DAY(+$D$2-G4+285)<=15,TEXT(+$D$2-G4+285-20,"Mmm")&"-"&TEXT(+$D$2-G4+285,"mmm"),TEXT(+$D$2-G4+285,"Mmm")&"-"&TEXT(+$D$2-G4+285+20,"mmm")),""),"xxxxx") | M4: Morreu | N4: Relatório de Manejo Reprodutivo e Comercial - Fazenda Visita do veterinário Márcio Reis em 11/11/25 para efetuar uma sessão de TOQUE em MATRIZES ocorrendo [a] visita do veterinário Márcio Reis em 11/11/25 para realização de TOQUE em 88 matrizes, incluindo 20 novilhas (bezerras prematuras), ocorrendo o resultado a [seguir]: [Uma matriz] descartada para Arlindo com 12@ em 24/12/25. [Resultado a] seguir: 26 matrizes CH (Cheias) e 62 matrizes VZ (Vazias). Analisando as 62 matrizes VZ teremos: 32 matrizes com bezerros ao pé, nascidos entre 01 a 90 dias passados. 08 bezerros nascidos [identificados pelos números]: 939, 946, 973, 984, 988, 990, 1012, 1020, 1042, 1045, 1053, 1058, 1063, 1064, 1065, 1066, 1067. Ocorrências e Observações: Perdida no bambuzal: [Matriz identificada como] Mor[ta]. deb[ilitada]. após atol[amento] em 12/02/2026. Bezerro criado pela [vaca] 1021 [por] 120 dias. Restando 22 matrizes para serem analisadas, [sendo estas] as matrizes com mais de 90 dias de paridas. Feito o remanejamento dos reprodutores das propriedades. Análise de Descarte e Vendas: Após análise da situação reprodutiva das matrizes com 10 a 15 crias, resultando em um grupo de 11 unidades, as quais foram negociadas por 33@ [cada ou total]. Durante o ano de 2025 foram incorporadas ao rebanho 15 bezerras em janeiro e 05 em dezembro/25, de acordo com o programa SUBMAT (renovação de matrizes). Após análise criteriosa, chegamos a 20 [matrizes] para DESCARTE: Venda 1 (10/02/26): Vendidas 10 matrizes para Luciano Moraes, que foram: 858, 859, 876, 899, 939, 934, 943, 945, 946, 1042, para DESCARTE, no total de 100@. Venda 2 (15/04/26): Vendidas para Luciano Moraes para DESCARTE as matrizes: 863, 867, 893, 957, 959, 963, 964, 984 e 992, em um total de 120@. Nota: [A matriz da] Mat[éria] deb[ilitada] mor[reu] em 01/02/26. Bezerro criado pela [vaca] 1021. Outras Baixas: Morreu mordida por cobra. MORREU [sem causa especificada]. Para descarte [pendente]. | XFD4: 1
A5: =IF(G5="VZ","",I5&COUNTIF($I$4:I4,I5)+1)&IF(K5>0,"-N","") -> 2 | B5: =+Matrizes!B6 -> 0 | C5: =+Matrizes!C6 -> 858 | D5: =+Matrizes!E6 -> 45548 | E5: =+Matrizes!G6 -> 13 | F5: =IFERROR(+Matrizes!H6,"") -> 15.369231 | H5: =IFERROR(IF(G5>0,+$D$2-G5+285,""),"xxxxx") | I5: =IFERROR(IF(G5>0,IF(DAY(+$D$2-G5+285)<=15,TEXT(+$D$2-G5+285-20,"Mmm")&"-"&TEXT(+$D$2-G5+285,"mmm"),TEXT(+$D$2-G5+285,"Mmm")&"-"&TEXT(+$D$2-G5+285+20,"mmm")),""),"xxxxx")
A6: =IF(G6="VZ","",I6&COUNTIF($I$4:I5,I6)+1)&IF(K6>0,"-N","") -> 3 | B6: =+Matrizes!B7 -> 0 | C6: 859 | D6: 44792 | E6: 12 | F6: 15.01 | H6: =IFERROR(IF(G6>0,+$D$2-G6+285,""),"xxxxx") | I6: =IFERROR(IF(G6>0,IF(DAY(+$D$2-G6+285)<=15,TEXT(+$D$2-G6+285-20,"Mmm")&"-"&TEXT(+$D$2-G6+285,"mmm"),TEXT(+$D$2-G6+285,"Mmm")&"-"&TEXT(+$D$2-G6+285+20,"mmm")),""),"xxxxx")
A7: =IF(G7="VZ","",I7&COUNTIF($I$4:I6,I7)+1)&IF(K7>0,"-N","") -> dez-jan1-N | B7: =+Matrizes!B8 -> 1 | C7: =+Matrizes!C8 -> 860 | D7: =+Matrizes!E8 -> 46045 | E7: =+Matrizes!G8 -> 12 | F7: =IFERROR(+Matrizes!H8,"") -> 17.311111 | G7: 240 | H7: =IFERROR(IF(G7>0,+$D$2-G7+285,""),"xxxxx") -> 46019 | I7: =IFERROR(IF(G7>0,IF(DAY(+$D$2-G7+285)<=15,TEXT(+$D$2-G7+285-20,"Mmm")&"-"&TEXT(+$D$2-G7+285,"mmm"),TEXT(+$D$2-G7+285,"Mmm")&"-"&TEXT(+$D$2-G7+285+20,"mmm")),""),"xxxxx") -> dez-jan | J7: nel.1 | K7: 46045 | L7: F | M7: 1153
A8: =IF(G8="VZ","",I8&COUNTIF($I$4:I7,I8)+1)&IF(K8>0,"-N","") -> 4 | B8: =+Matrizes!B9 -> 0 | C8: =+Matrizes!C9 -> 862 | D8: =+Matrizes!E9 -> 44893 | E8: =+Matrizes!G9 -> 12 | F8: =IFERROR(+Matrizes!H9,"") -> 14.825 | H8: =IFERROR(IF(G8>0,+$D$2-G8+285,""),"xxxxx") | I8: =IFERROR(IF(G8>0,IF(DAY(+$D$2-G8+285)<=15,TEXT(+$D$2-G8+285-20,"Mmm")&"-"&TEXT(+$D$2-G8+285,"mmm"),TEXT(+$D$2-G8+285,"Mmm")&"-"&TEXT(+$D$2-G8+285+20,"mmm")),""),"xxxxx") | M8: P/DESCARTE | XFD8: 1
A9: =IF(G9="VZ","",I9&COUNTIF($I$4:I8,I9)+1)&IF(K9>0,"-N","") -> -N | B9: =+Matrizes!B10 -> 2 | C9: =+Matrizes!C10 -> 863 | D9: =+Matrizes!E10 -> 45486 | E9: =+Matrizes!G10 -> 13 | F9: =IFERROR(+Matrizes!H10,"") -> 15.705128 | G9: VZ | H9: =IFERROR(IF(G9>0,+$D$2-G9+285,""),"xxxxx") -> xxxxx | I9: =IFERROR(IF(G9>0,IF(DAY(+$D$2-G9+285)<=15,TEXT(+$D$2-G9+285-20,"Mmm")&"-"&TEXT(+$D$2-G9+285,"mmm"),TEXT(+$D$2-G9+285,"Mmm")&"-"&TEXT(+$D$2-G9+285+20,"mmm")),""),"xxxxx") -> xxxxx | K9: descartada
A10: =IF(G10="VZ","",I10&COUNTIF($I$4:I9,I10)+1)&IF(K10>0,"-N","") -> 5 | B10: =+Matrizes!B11 -> 0 | C10: =+Matrizes!C11 -> 865 | D10: =+Matrizes!E11 -> 45196 | E10: =+Matrizes!G11 -> 12 | F10: =IFERROR(+Matrizes!H11,"") -> 15.141667 | H10: =IFERROR(IF(G10>0,+$D$2-G10+285,""),"xxxxx") | I10: =IFERROR(IF(G10>0,IF(DAY(+$D$2-G10+285)<=15,TEXT(+$D$2-G10+285-20,"Mmm")&"-"&TEXT(+$D$2-G10+285,"mmm"),TEXT(+$D$2-G10+285,"Mmm")&"-"&TEXT(+$D$2-G10+285+20,"mmm")),""),"xxxxx") | M10: Morreu | XFD10: 1
A11: =IF(G11="VZ","",I11&COUNTIF($I$4:I10,I11)+1)&IF(K11>0,"-N","") -> nov-dez1-N | B11: =+Matrizes!B12 -> 3 | C11: =+Matrizes!C12 -> 867 | D11: =+Matrizes!E12 -> 45944 | E11: =+Matrizes!G12 -> 15 | F11: =IFERROR(+Matrizes!H12,"") -> 13.74 | G11: 270 | H11: =IFERROR(IF(G11>0,+$D$2-G11+285,""),"xxxxx") -> 45989 | I11: =IFERROR(IF(G11>0,IF(DAY(+$D$2-G11+285)<=15,TEXT(+$D$2-G11+285-20,"Mmm")&"-"&TEXT(+$D$2-G11+285,"mmm"),TEXT(+$D$2-G11+285,"Mmm")&"-"&TEXT(+$D$2-G11+285+20,"mmm")),""),"xxxxx") -> nov-dez | J11: Nel.1 | K11: 45944 | L11: M | M11: 1136
A12: =IF(G12="VZ","",I12&COUNTIF($I$4:I11,I12)+1)&IF(K12>0,"-N","") -> 6 | B12: =+Matrizes!B13 -> 0 | C12: =+Matrizes!C13 -> 869 | D12: =+Matrizes!E13 -> 44646 | E12: =+Matrizes!G13 -> 10 | F12: =IFERROR(+Matrizes!H13,"") -> 16.966667 | H12: =IFERROR(IF(G12>0,+$D$2-G12+285,""),"xxxxx") | I12: =IFERROR(IF(G12>0,IF(DAY(+$D$2-G12+285)<=15,TEXT(+$D$2-G12+285-20,"Mmm")&"-"&TEXT(+$D$2-G12+285,"mmm"),TEXT(+$D$2-G12+285,"Mmm")&"-"&TEXT(+$D$2-G12+285+20,"mmm")),""),"xxxxx") | M12: P/DESCARTE | XFD12: 1
A13: =IF(G13="VZ","",I13&COUNTIF($I$4:I12,I13)+1)&IF(K13>0,"-N","") -> 7 | B13: =+Matrizes!B14 -> 0 | C13: =+Matrizes!C14 -> 870 | D13: =+Matrizes!E14 -> 44605 | E13: =+Matrizes!G14 -> 13 | F13: =IFERROR(+Matrizes!H14,"") -> 13.389744 | H13: =IFERROR(IF(G13>0,+$D$2-G13+285,""),"xxxxx") | I13: =IFERROR(IF(G13>0,IF(DAY(+$D$2-G13+285)<=15,TEXT(+$D$2-G13+285-20,"Mmm")&"-"&TEXT(+$D$2-G13+285,"mmm"),TEXT(+$D$2-G13+285,"Mmm")&"-"&TEXT(+$D$2-G13+285+20,"mmm")),""),"xxxxx") | M13: Morreu | XFD13: 1
A14: =IF(G14="VZ","",I14&COUNTIF($I$4:I13,I14)+1)&IF(K14>0,"-N","") -> 8 | B14: =+Matrizes!B15 -> 0 | C14: =+Matrizes!C15 -> 871 | D14: =+Matrizes!E15 -> 43423 | E14: =+Matrizes!G15 -> 10 | F14: =IFERROR(+Matrizes!H15,"") -> 13.613333 | H14: =IFERROR(IF(G14>0,+$D$2-G14+285,""),"xxxxx") | I14: =IFERROR(IF(G14>0,IF(DAY(+$D$2-G14+285)<=15,TEXT(+$D$2-G14+285-20,"Mmm")&"-"&TEXT(+$D$2-G14+285,"mmm"),TEXT(+$D$2-G14+285,"Mmm")&"-"&TEXT(+$D$2-G14+285+20,"mmm")),""),"xxxxx")
A15: =IF(G15="VZ","",I15&COUNTIF($I$4:I14,I15)+1)&IF(K15>0,"-N","") -> 9 | B15: =+Matrizes!B16 -> 0 | C15: =+Matrizes!C16 -> 872 | D15: =+Matrizes!E16 -> 43834 | E15: =+Matrizes!G16 -> 11 | F15: =IFERROR(+Matrizes!H16,"") -> 13.484848 | H15: =IFERROR(IF(G15>0,+$D$2-G15+285,""),"xxxxx") | I15: =IFERROR(IF(G15>0,IF(DAY(+$D$2-G15+285)<=15,TEXT(+$D$2-G15+285-20,"Mmm")&"-"&TEXT(+$D$2-G15+285,"mmm"),TEXT(+$D$2-G15+285,"Mmm")&"-"&TEXT(+$D$2-G15+285+20,"mmm")),""),"xxxxx")
A16: =IF(G16="VZ","",I16&COUNTIF($I$4:I15,I16)+1)&IF(K16>0,"-N","") -> 10 | B16: =+Matrizes!B17 -> 0 | C16: =+Matrizes!C17 -> 873 | D16: =+Matrizes!E17 -> 45369 | E16: =+Matrizes!G17 -> 15 | F16: =IFERROR(+Matrizes!H17,"") -> 13.2 | H16: =IFERROR(IF(G16>0,+$D$2-G16+285,""),"xxxxx") | I16: =IFERROR(IF(G16>0,IF(DAY(+$D$2-G16+285)<=15,TEXT(+$D$2-G16+285-20,"Mmm")&"-"&TEXT(+$D$2-G16+285,"mmm"),TEXT(+$D$2-G16+285,"Mmm")&"-"&TEXT(+$D$2-G16+285+20,"mmm")),""),"xxxxx")
A17: =IF(G17="VZ","",I17&COUNTIF($I$4:I16,I17)+1)&IF(K17>0,"-N","") -> mar-abr1-N | B17: =+Matrizes!B18 -> 4 | C17: =+Matrizes!C18 -> 874 | D17: =+Matrizes!E18 -> 46105 | E17: 15 | F17: =IFERROR(+Matrizes!H18,"") -> 18.180556 | G17: 160 | H17: =IFERROR(IF(G17>0,+$D$2-G17+285,""),"xxxxx") -> 46099 | I17: =IFERROR(IF(G17>0,IF(DAY(+$D$2-G17+285)<=15,TEXT(+$D$2-G17+285-20,"Mmm")&"-"&TEXT(+$D$2-G17+285,"mmm"),TEXT(+$D$2-G17+285,"Mmm")&"-"&TEXT(+$D$2-G17+285+20,"mmm")),""),"xxxxx") -> mar-abr | J17: nel.02 | K17: 46105 | L17: M | M17: 1161
A18: =IF(G18="VZ","",I18&COUNTIF($I$4:I17,I18)+1)&IF(K18>0,"-N","") -> 11 | B18: =+Matrizes!B19 -> 0 | C18: =+Matrizes!C19 -> 875 | D18: =+Matrizes!E19 -> 44197 | E18: =+Matrizes!G19 -> 10 | F18: =IFERROR(+Matrizes!H19,"") -> 15.433333 | H18: =IFERROR(IF(G18>0,+$D$2-G18+285,""),"xxxxx") | I18: =IFERROR(IF(G18>0,IF(DAY(+$D$2-G18+285)<=15,TEXT(+$D$2-G18+285-20,"Mmm")&"-"&TEXT(+$D$2-G18+285,"mmm"),TEXT(+$D$2-G18+285,"Mmm")&"-"&TEXT(+$D$2-G18+285+20,"mmm")),""),"xxxxx")
A19: =IF(G19="VZ","",I19&COUNTIF($I$4:I18,I19)+1)&IF(K19>0,"-N","") -> -N | B19: 8 | C19: =+Matrizes!C20 -> 876 | D19: =+Matrizes!E20 -> 45673 | E19: =+Matrizes!G20 -> 14 | F19: =IFERROR(+Matrizes!H20,"") -> 14.542857 | G19: VZ | H19: =IFERROR(IF(G19>0,+$D$2-G19+285,""),"xxxxx") -> xxxxx | I19: =IFERROR(IF(G19>0,IF(DAY(+$D$2-G19+285)<=15,TEXT(+$D$2-G19+285-20,"Mmm")&"-"&TEXT(+$D$2-G19+285,"mmm"),TEXT(+$D$2-G19+285,"Mmm")&"-"&TEXT(+$D$2-G19+285+20,"mmm")),""),"xxxxx") -> xxxxx | K19: descartada
A20: =IF(G20="VZ","",I20&COUNTIF($I$4:I19,I20)+1)&IF(K20>0,"-N","") -> 12 | B20: =+Matrizes!B21 -> 0 | C20: =+Matrizes!C21 -> 877 | D20: =+Matrizes!E21 -> 44510 | E20: =+Matrizes!G21 -> 12 | F20: =IFERROR(+Matrizes!H21,"") -> 13.780556 | H20: =IFERROR(IF(G20>0,+$D$2-G20+285,""),"xxxxx") | I20: =IFERROR(IF(G20>0,IF(DAY(+$D$2-G20+285)<=15,TEXT(+$D$2-G20+285-20,"Mmm")&"-"&TEXT(+$D$2-G20+285,"mmm"),TEXT(+$D$2-G20+285,"Mmm")&"-"&TEXT(+$D$2-G20+285+20,"mmm")),""),"xxxxx") | M20: P/DESCARTE | XFD20: 1
A21: =IF(G21="VZ","",I21&COUNTIF($I$4:I20,I21)+1)&IF(K21>0,"-N","") -> 13 | B21: =+Matrizes!B22 -> 0 | C21: =+Matrizes!C22 -> 880 | D21: =+Matrizes!E22 -> 44821 | E21: =+Matrizes!G22 -> 12 | F21: =IFERROR(+Matrizes!H22,"") -> 14.875 | H21: =IFERROR(IF(G21>0,+$D$2-G21+285,""),"xxxxx") | I21: =IFERROR(IF(G21>0,IF(DAY(+$D$2-G21+285)<=15,TEXT(+$D$2-G21+285-20,"Mmm")&"-"&TEXT(+$D$2-G21+285,"mmm"),TEXT(+$D$2-G21+285,"Mmm")&"-"&TEXT(+$D$2-G21+285+20,"mmm")),""),"xxxxx") | M21: P/DESCARTE | XFD21: 1
A22: =IF(G22="VZ","",I22&COUNTIF($I$4:I21,I22)+1)&IF(K22>0,"-N","") -> 14 | B22: =+Matrizes!B23 -> 0 | C22: =+Matrizes!C23 -> 881 | D22: =+Matrizes!E23 -> 45684 | E22: =+Matrizes!G23 -> 15 | F22: =IFERROR(+Matrizes!H23,"") -> 13.813333 | H22: =IFERROR(IF(G22>0,+$D$2-G22+285,""),"xxxxx") | I22: =IFERROR(IF(G22>0,IF(DAY(+$D$2-G22+285)<=15,TEXT(+$D$2-G22+285-20,"Mmm")&"-"&TEXT(+$D$2-G22+285,"mmm"),TEXT(+$D$2-G22+285,"Mmm")&"-"&TEXT(+$D$2-G22+285+20,"mmm")),""),"xxxxx")
A23: =IF(G23="VZ","",I23&COUNTIF($I$4:I22,I23)+1)&IF(K23>0,"-N","") -> 15 | B23: =+Matrizes!B24 -> 0 | C23: =+Matrizes!C24 -> 882 | D23: =+Matrizes!E24 -> 44287 | E23: =+Matrizes!G24 -> 11 | F23: =IFERROR(+Matrizes!H24,"") -> 14.975758 | H23: =IFERROR(IF(G23>0,+$D$2-G23+285,""),"xxxxx") | I23: =IFERROR(IF(G23>0,IF(DAY(+$D$2-G23+285)<=15,TEXT(+$D$2-G23+285-20,"Mmm")&"-"&TEXT(+$D$2-G23+285,"mmm"),TEXT(+$D$2-G23+285,"Mmm")&"-"&TEXT(+$D$2-G23+285+20,"mmm")),""),"xxxxx") | M23: P/DESCARTE | XFD23: 1
A24: =IF(G24="VZ","",I24&COUNTIF($I$4:I23,I24)+1)&IF(K24>0,"-N","") -> 16 | B24: =+Matrizes!B25 -> 0 | C24: =+Matrizes!C25 -> 884 | D24: =+Matrizes!E25 -> 44939 | E24: =+Matrizes!G25 -> 12 | F24: =IFERROR(+Matrizes!H25,"") -> 14.919444 | H24: =IFERROR(IF(G24>0,+$D$2-G24+285,""),"xxxxx") | I24: =IFERROR(IF(G24>0,IF(DAY(+$D$2-G24+285)<=15,TEXT(+$D$2-G24+285-20,"Mmm")&"-"&TEXT(+$D$2-G24+285,"mmm"),TEXT(+$D$2-G24+285,"Mmm")&"-"&TEXT(+$D$2-G24+285+20,"mmm")),""),"xxxxx") | M24: P/DESCARTE | XFD24: 1
A25: =IF(G25="VZ","",I25&COUNTIF($I$4:I24,I25)+1)&IF(K25>0,"-N","") -> 17 | B25: =+Matrizes!B26 -> 0 | C25: =+Matrizes!C26 -> 885 | D25: =+Matrizes!E26 -> 44894 | E25: =+Matrizes!G26 -> 12 | F25: =IFERROR(+Matrizes!H26,"") -> 14.85 | H25: =IFERROR(IF(G25>0,+$D$2-G25+285,""),"xxxxx") | I25: =IFERROR(IF(G25>0,IF(DAY(+$D$2-G25+285)<=15,TEXT(+$D$2-G25+285-20,"Mmm")&"-"&TEXT(+$D$2-G25+285,"mmm"),TEXT(+$D$2-G25+285,"Mmm")&"-"&TEXT(+$D$2-G25+285+20,"mmm")),""),"xxxxx") | M25: P/DESCARTE | XFD25: 1
A26: =IF(G26="VZ","",I26&COUNTIF($I$4:I25,I26)+1)&IF(K26>0,"-N","") -> 18 | B26: =+Matrizes!B27 -> 0 | C26: =+Matrizes!C27 -> 886 | D26: =+Matrizes!E27 -> 45404 | E26: =+Matrizes!G27 -> 14 | F26: =IFERROR(+Matrizes!H27,"") -> 14.130952 | H26: =IFERROR(IF(G26>0,+$D$2-G26+285,""),"xxxxx") | I26: =IFERROR(IF(G26>0,IF(DAY(+$D$2-G26+285)<=15,TEXT(+$D$2-G26+285-20,"Mmm")&"-"&TEXT(+$D$2-G26+285,"mmm"),TEXT(+$D$2-G26+285,"Mmm")&"-"&TEXT(+$D$2-G26+285+20,"mmm")),""),"xxxxx")
A27: =IF(G27="VZ","",I27&COUNTIF($I$4:I26,I27)+1)&IF(K27>0,"-N","") -> 19 | B27: =+Matrizes!B28 -> 0 | C27: =+Matrizes!C28 -> 889 | D27: =+Matrizes!E28 -> 44860 | E27: =+Matrizes!G28 -> 12 | F27: =IFERROR(+Matrizes!H28,"") -> 15.194444 | H27: =IFERROR(IF(G27>0,+$D$2-G27+285,""),"xxxxx") | I27: =IFERROR(IF(G27>0,IF(DAY(+$D$2-G27+285)<=15,TEXT(+$D$2-G27+285-20,"Mmm")&"-"&TEXT(+$D$2-G27+285,"mmm"),TEXT(+$D$2-G27+285,"Mmm")&"-"&TEXT(+$D$2-G27+285+20,"mmm")),""),"xxxxx") | M27: Morreu | XFD27: 1
A28: =IF(G28="VZ","",I28&COUNTIF($I$4:I27,I28)+1)&IF(K28>0,"-N","") -> -N | B28: =+Matrizes!B29 -> 5 | C28: =+Matrizes!C29 -> 893 | D28: =+Matrizes!E29 -> 45835 | E28: =+Matrizes!G29 -> 12 | F28: =IFERROR(+Matrizes!H29,"") -> 17.138889 | G28: VZ | H28: =IFERROR(IF(G28>0,+$D$2-G28+285,""),"xxxxx") -> xxxxx | I28: =IFERROR(IF(G28>0,IF(DAY(+$D$2-G28+285)<=15,TEXT(+$D$2-G28+285-20,"Mmm")&"-"&TEXT(+$D$2-G28+285,"mmm"),TEXT(+$D$2-G28+285,"Mmm")&"-"&TEXT(+$D$2-G28+285+20,"mmm")),""),"xxxxx") -> xxxxx | K28: descartada
A29: =IF(G29="VZ","",I29&COUNTIF($I$4:I28,I29)+1)&IF(K29>0,"-N","") -> 20 | B29: =+Matrizes!B30 -> 0 | C29: =+Matrizes!C30 -> 894 | D29: =+Matrizes!E30 -> 45792 | E29: =+Matrizes!G30 -> 13 | F29: =IFERROR(+Matrizes!H30,"") -> 15.979487 | H29: =IFERROR(IF(G29>0,+$D$2-G29+285,""),"xxxxx") | I29: =IFERROR(IF(G29>0,IF(DAY(+$D$2-G29+285)<=15,TEXT(+$D$2-G29+285-20,"Mmm")&"-"&TEXT(+$D$2-G29+285,"mmm"),TEXT(+$D$2-G29+285,"Mmm")&"-"&TEXT(+$D$2-G29+285+20,"mmm")),""),"xxxxx")
A30: =IF(G30="VZ","",I30&COUNTIF($I$4:I29,I30)+1)&IF(K30>0,"-N","") -> 21 | B30: =+Matrizes!B31 -> 0 | C30: =+Matrizes!C31 -> 896 | D30: =+Matrizes!E31 -> 43476 | E30: =+Matrizes!G31 -> 9 | F30: =IFERROR(+Matrizes!H31,"") -> 14.385185 | H30: =IFERROR(IF(G30>0,+$D$2-G30+285,""),"xxxxx") | I30: =IFERROR(IF(G30>0,IF(DAY(+$D$2-G30+285)<=15,TEXT(+$D$2-G30+285-20,"Mmm")&"-"&TEXT(+$D$2-G30+285,"mmm"),TEXT(+$D$2-G30+285,"Mmm")&"-"&TEXT(+$D$2-G30+285+20,"mmm")),""),"xxxxx")
A31: =IF(G31="VZ","",I31&COUNTIF($I$4:I30,I31)+1)&IF(K31>0,"-N","") -> 22 | B31: =+Matrizes!B32 -> 0 | C31: =+Matrizes!C32 -> 897 | D31: =+Matrizes!E32 -> 43692 | E31: =+Matrizes!G32 -> 10 | F31: =IFERROR(+Matrizes!H32,"") -> 14.076667 | H31: =IFERROR(IF(G31>0,+$D$2-G31+285,""),"xxxxx") | I31: =IFERROR(IF(G31>0,IF(DAY(+$D$2-G31+285)<=15,TEXT(+$D$2-G31+285-20,"Mmm")&"-"&TEXT(+$D$2-G31+285,"mmm"),TEXT(+$D$2-G31+285,"Mmm")&"-"&TEXT(+$D$2-G31+285+20,"mmm")),""),"xxxxx")
A32: =IF(G32="VZ","",I32&COUNTIF($I$4:I31,I32)+1)&IF(K32>0,"-N","") -> 23 | B32: =+Matrizes!B33 -> 0 | C32: =+Matrizes!C33 -> 898 | D32: =+Matrizes!E33 -> 44431 | E32: =+Matrizes!G33 -> 12 | F32: =IFERROR(+Matrizes!H33,"") -> 13.686111 | H32: =IFERROR(IF(G32>0,+$D$2-G32+285,""),"xxxxx") | I32: =IFERROR(IF(G32>0,IF(DAY(+$D$2-G32+285)<=15,TEXT(+$D$2-G32+285-20,"Mmm")&"-"&TEXT(+$D$2-G32+285,"mmm"),TEXT(+$D$2-G32+285,"Mmm")&"-"&TEXT(+$D$2-G32+285+20,"mmm")),""),"xxxxx") | M32: P/DESCARTE | XFD32: 1
A33: =IF(G33="VZ","",I33&COUNTIF($I$4:I32,I33)+1)&IF(K33>0,"-N","") -> 24 | B33: =+Matrizes!B34 -> 0 | C33: =+Matrizes!C34 -> 899 | D33: =+Matrizes!E34 -> 45881 | E33: =+Matrizes!G34 -> 14 | F33: =IFERROR(+Matrizes!H34,"") -> 14.740476 | H33: =IFERROR(IF(G33>0,+$D$2-G33+285,""),"xxxxx") | I33: =IFERROR(IF(G33>0,IF(DAY(+$D$2-G33+285)<=15,TEXT(+$D$2-G33+285-20,"Mmm")&"-"&TEXT(+$D$2-G33+285,"mmm"),TEXT(+$D$2-G33+285,"Mmm")&"-"&TEXT(+$D$2-G33+285+20,"mmm")),""),"xxxxx")
A34: =IF(G34="VZ","",I34&COUNTIF($I$4:I33,I34)+1)&IF(K34>0,"-N","") -> 25 | B34: =+Matrizes!B35 -> 0 | C34: =+Matrizes!C35 -> 926 | D34: =+Matrizes!E35 -> 45628 | E34: =+Matrizes!G35 -> 14 | F34: =IFERROR(+Matrizes!H35,"") -> 14.466667 | H34: =IFERROR(IF(G34>0,+$D$2-G34+285,""),"xxxxx") | I34: =IFERROR(IF(G34>0,IF(DAY(+$D$2-G34+285)<=15,TEXT(+$D$2-G34+285-20,"Mmm")&"-"&TEXT(+$D$2-G34+285,"mmm"),TEXT(+$D$2-G34+285,"Mmm")&"-"&TEXT(+$D$2-G34+285+20,"mmm")),""),"xxxxx")
A35: =IF(G35="VZ","",I35&COUNTIF($I$4:I34,I35)+1)&IF(K35>0,"-N","") -> 26 | B35: =+Matrizes!B36 -> 0 | C35: =+Matrizes!C36 -> 930 | D35: =+Matrizes!E36 -> 45991 | E35: =+Matrizes!G36 -> 13 | F35: =IFERROR(+Matrizes!H36,"") -> 15.964103 | H35: =IFERROR(IF(G35>0,+$D$2-G35+285,""),"xxxxx") | I35: =IFERROR(IF(G35>0,IF(DAY(+$D$2-G35+285)<=15,TEXT(+$D$2-G35+285-20,"Mmm")&"-"&TEXT(+$D$2-G35+285,"mmm"),TEXT(+$D$2-G35+285,"Mmm")&"-"&TEXT(+$D$2-G35+285+20,"mmm")),""),"xxxxx") | L35: F | M35: 1149
A36: =IF(G36="VZ","",I36&COUNTIF($I$4:I35,I36)+1)&IF(K36>0,"-N","") -> mar-abr2 | B36: =+Matrizes!B37 -> 6 | C36: =+Matrizes!C37 -> 931 | D36: =+Matrizes!E37 -> 45393 | E36: =+Matrizes!G37 -> 12 | F36: =IFERROR(+Matrizes!H37,"") -> 15.575 | G36: 150 | H36: =IFERROR(IF(G36>0,+$D$2-G36+285,""),"xxxxx") -> 46109 | I36: =IFERROR(IF(G36>0,IF(DAY(+$D$2-G36+285)<=15,TEXT(+$D$2-G36+285-20,"Mmm")&"-"&TEXT(+$D$2-G36+285,"mmm"),TEXT(+$D$2-G36+285,"Mmm")&"-"&TEXT(+$D$2-G36+285+20,"mmm")),""),"xxxxx") -> mar-abr
A37: =IF(G37="VZ","",I37&COUNTIF($I$4:I36,I37)+1)&IF(K37>0,"-N","") -> 27 | B37: =+Matrizes!B38 -> 0 | C37: =+Matrizes!C38 -> 933 | D37: =+Matrizes!E38 -> 45174 | E37: =+Matrizes!G38 -> 14 | F37: =IFERROR(+Matrizes!H38,"") -> 12.859524 | H37: =IFERROR(IF(G37>0,+$D$2-G37+285,""),"xxxxx") | I37: =IFERROR(IF(G37>0,IF(DAY(+$D$2-G37+285)<=15,TEXT(+$D$2-G37+285-20,"Mmm")&"-"&TEXT(+$D$2-G37+285,"mmm"),TEXT(+$D$2-G37+285,"Mmm")&"-"&TEXT(+$D$2-G37+285+20,"mmm")),""),"xxxxx")
A38: =IF(G38="VZ","",I38&COUNTIF($I$4:I37,I38)+1)&IF(K38>0,"-N","") -> 28 | B38: =+Matrizes!B39 -> 0 | C38: =+Matrizes!C39 -> 934 | D38: =+Matrizes!E39 -> 45953 | E38: =+Matrizes!G39 -> 13 | F38: =IFERROR(+Matrizes!H39,"") -> 15.84359 | H38: =IFERROR(IF(G38>0,+$D$2-G38+285,""),"xxxxx") | I38: =IFERROR(IF(G38>0,IF(DAY(+$D$2-G38+285)<=15,TEXT(+$D$2-G38+285-20,"Mmm")&"-"&TEXT(+$D$2-G38+285,"mmm"),TEXT(+$D$2-G38+285,"Mmm")&"-"&TEXT(+$D$2-G38+285+20,"mmm")),""),"xxxxx") | L38: F | M38: 1043
A39: =IF(G39="VZ","",I39&COUNTIF($I$4:I38,I39)+1)&IF(K39>0,"-N","") -> 29 | B39: =+Matrizes!B40 -> 0 | C39: =+Matrizes!C40 -> 936 | D39: =+Matrizes!E40 -> 44993 | E39: =+Matrizes!G40 -> 12 | F39: =IFERROR(+Matrizes!H40,"") -> 14.508333 | H39: =IFERROR(IF(G39>0,+$D$2-G39+285,""),"xxxxx") | I39: =IFERROR(IF(G39>0,IF(DAY(+$D$2-G39+285)<=15,TEXT(+$D$2-G39+285-20,"Mmm")&"-"&TEXT(+$D$2-G39+285,"mmm"),TEXT(+$D$2-G39+285,"Mmm")&"-"&TEXT(+$D$2-G39+285+20,"mmm")),""),"xxxxx")
A40: =IF(G40="VZ","",I40&COUNTIF($I$4:I39,I40)+1)&IF(K40>0,"-N","") -> 30 | B40: =+Matrizes!B41 -> 0 | C40: =+Matrizes!C41 -> 939 | D40: =+Matrizes!E41 -> 45642 | E40: =+Matrizes!G41 -> 12 | F40: =IFERROR(+Matrizes!H41,"") -> 16.230556 | H40: =IFERROR(IF(G40>0,+$D$2-G40+285,""),"xxxxx") | I40: =IFERROR(IF(G40>0,IF(DAY(+$D$2-G40+285)<=15,TEXT(+$D$2-G40+285-20,"Mmm")&"-"&TEXT(+$D$2-G40+285,"mmm"),TEXT(+$D$2-G40+285,"Mmm")&"-"&TEXT(+$D$2-G40+285+20,"mmm")),""),"xxxxx")
...

Sheet Compradores
A3: Rótulos de Linha | B3: Soma de Preço Real | C3: Contagem de Reg.Nasc.
A4: não registrado | C4: 266
A5: Marcos Torres | B5: 261051 | C5: 189
A6: Jamilton Santos-Ca | B6: 163407 | C6: 164
A7: Luciano Costa/Cassarang. | B7: 121324 | C7: 64
A8: Divo Amoedo | B8: 56626 | C8: 58
A9: Erico Hardt | B9: 40344 | C9: 41
A10: Miro/Cand. | B10: 83151 | C10: 39
A11: Morto | B11: 0 | C11: 37
A12: Roque/Davi | B12: 66664 | C12: 26
A13: Domingos Costa/Cand. | B13: 57675 | C13: 25
A14: Neto/Muritiba | B14: 43146 | C14: 18
A15: Arlindo Paramirim | B15: 4698 | C15: 3
A16: JorgeCacho | B16: 800 | C16: 2
A17: SUBAMAT | C17: 2
A18: Carlos/faz.s.francisco | B18: 5119 | C18: 2
A19: Roubada | B19: 0 | C19: 2
A20: Tua | B20: 3900 | C20: 1
A21: Agnaldo/Sabino | B21: 1250 | C21: 1
A22: Chico Bambu | C22: 1
A23: Total Geral | B23: 909155 | C23: 941

Sheet Plan1
A1: Invest/Retorno | B1: Data | C1: Períodos (Mês) | D1: Acum | E1: Rend
A2: 2885 | B2: 41913 | D2: =-FV($F$2,C2,0,A2) -> 2885
A3: 1509 | B3: 43132 | C3: =+(B3-$B$2)/365*12 -> 40.076712 | D3: =+A3+D2 -> 4394 | E3: =RATE(C3,0,-D2,D3) -> 0.010553039
A4: 1012 | B4: 43313 | C4: =+(B4-$B$2)/365*12 -> 46.027397 | D4: =+D3+A4 -> 5406 | E4: =RATE(C4,0,-D2,D4) -> 0.013737212
A5: 2045 | B5: 44378 | C5: =+(B5-$B$2)/365*12 -> 81.041096 | D5: =+D4+A5 -> 7451 | E5: =RATE(C5,0,-D3,D5) -> 0.006537828
